<?xml version="1.0"?>
<robot xmlns:xacro="http://www.ros.org/wiki/xacro">
	
    <xacro:include filename="inertial_macros.xacro"/>

    <material name="white">
        <color rgba="0.5 0.5 0.5 1"/>		
    </material>

    <material name="black">
		<color rgba="0 0 0 1"/>
    </material>

    <!-- BASE LINK -->

    <link name="base_link">

    </link>

	<!-- left ft slot -->
	<joint name="left_ft_joint" type="fixed">
		<parent link="base_link"/>
		<child link="left_ft_link"/>
		<origin xyz="0.185 0.225 0.134" rpy="${pi/2} 0 0"/>
		<axis xyz="0 0 1"/>
	</joint>

	<link name="left_ft_link">
		<visual>
			<origin xyz="0 0 0.1"/>
			<geometry>
				<mesh filename="package://holonomic/meshes/2020_AL-Profile.stl" scale="0.001 0.001 0.025"/>
			</geometry>
			<material name="white"/>
		</visual>

		<collision>
			<origin xyz="0 0 0.1"/>
			<geometry>
				<box size="0.0 0.0 0.0"/>
			</geometry>
		</collision>

		<xacro:inertial_box mass="0.2" x="0.5" y="0.5" z="0.03">
        	<origin xyz="0 0 0.1" rpy="0 0 0"/>
    	</xacro:inertial_box>
	</link>

	<!-- left bt slot -->
	<joint name="left_bt_joint" type="fixed">
		<parent link="base_link"/>
		<child link="left_bt_link"/>
		<origin xyz="-0.205 0.225 0.134" rpy="${pi/2} 0 0"/>
		<axis xyz="0 0 1"/>
	</joint>

	<link name="left_bt_link">
		<visual>
			<origin xyz="0 0 0.1"/>
			<geometry>
				<mesh filename="package://holonomic/meshes/2020_AL-Profile.stl" scale="0.001 0.001 0.025"/>
			</geometry>
			<material name="white"/>
		</visual>

		<collision>
			<origin xyz="0 0 0.1"/>
			<geometry>
				<box size="0.0 0.0 0.0"/>
			</geometry>
		</collision>

		<xacro:inertial_box mass="0.2" x="0.5" y="0.5" z="0.03">
        	<origin xyz="0 0 0.1" rpy="0 0 0"/>
    	</xacro:inertial_box>
	</link>

	<!-- left ll slot -->
	<joint name="left_ll_joint" type="fixed">
		<parent link="base_link"/>
		<child link="left_ll_link"/>
		<origin xyz="-0.3 0.105 0.15" rpy="0 ${pi/2}  0"/>
		<axis xyz="0 0 1"/>
	</joint>

	<link name="left_ll_link">
		<visual>
			<origin xyz="0 0 0.1"/>
			<geometry>
				<mesh filename="package://holonomic/meshes/2020_AL-Profile.stl" scale="0.001 0.001 0.04"/>
			</geometry>
			<material name="white"/>
		</visual>

		<collision>
			<origin xyz="0 0 0.1"/>
			<geometry>
				<box size="0.0 0.0 0.0"/>
			</geometry>
		</collision>

		<xacro:inertial_box mass="0.2" x="0.5" y="0.5" z="0.03">
        	<origin xyz="0 0 0.1" rpy="0 0 0"/>
    	</xacro:inertial_box>
	</link>


	<!-- left lr slot -->
	<joint name="left_lr_joint" type="fixed">
		<parent link="base_link"/>
		<child link="left_lr_link"/>
		<origin xyz="-0.3 -0.125 0.15" rpy="0 ${pi/2}  0"/>
		<axis xyz="0 0 1"/>
	</joint>

	<link name="left_lr_link">
		<visual>
			<origin xyz="0 0 0.1"/>
			<geometry>
				<mesh filename="package://holonomic/meshes/2020_AL-Profile.stl" scale="0.001 0.001 0.04"/>
			</geometry>
			<material name="white"/>
		</visual>

		<collision>
			<origin xyz="0 0 0.1"/>
			<geometry>
				<box size="0.0 0.0 0.0"/>
			</geometry>
		</collision>

		<xacro:inertial_box mass="0.2" x="0.5" y="0.5" z="0.03">
        	<origin xyz="0 0 0.1" rpy="0 0 0"/>
    	</xacro:inertial_box>
	</link>

	<!-- servo fr -->
	<joint name="servo_fr_joint" type="fixed">
		<parent link="base_link"/>
		<child link="servo_fr_link"/>
		<origin xyz="0.19717 0.0 0.1" rpy="${pi/2} ${-pi/2} 0"/>
		<axis xyz="0 0 1"/>
	</joint>

	<link name="servo_fr_link">
		<visual>
			<origin xyz="0 0 0.1"/>
			<geometry>
				<mesh filename="package://holonomic/meshes/servomotor.stl" scale="0.0030 0.0030 0.0026"/>
			</geometry>
			<material name="white"/>
		</visual>

		<collision>
			<origin xyz="0 0 0.1"/>
			<geometry>
				<box size="0.0 0.0 0.0"/>
			</geometry>
		</collision>

		<xacro:inertial_box mass="0.2" x="0.5" y="0.5" z="0.03">
        	<origin xyz="0 0 0.1" rpy="0 0 0"/>
    	</xacro:inertial_box>
	</link>

	<!-- servo br -->
	<joint name="servo_br_joint" type="fixed">
		<parent link="base_link"/>
		<child link="servo_br_link"/>
		<origin xyz="-0.19717 0.0 0.1" rpy="${pi/2} ${-pi/2} 0"/>
		<axis xyz="0 0 1"/>
	</joint>

	<link name="servo_br_link">
		<visual>
			<origin xyz="0 0 0.1"/>
			<geometry>
				<mesh filename="package://holonomic/meshes/servomotor.stl" scale="0.0030 0.0030 0.0026"/>
			</geometry>
			<material name="white"/>
		</visual>

		<collision>
			<origin xyz="0 0 0.1"/>
			<geometry>
				<box size="0.0 0.0 0.0"/>
			</geometry>
		</collision>

		<xacro:inertial_box mass="0.2" x="0.5" y="0.5" z="0.03">
        	<origin xyz="0 0 0.1" rpy="0 0 0"/>
    	</xacro:inertial_box>
	</link>

	<!-- servo bl -->
	<joint name="servo_bl_joint" type="fixed">
		<parent link="base_link"/>
		<child link="servo_bl_link"/>
		<origin xyz="-0.19717 0.0 0.1" rpy="${-pi/2} ${-pi/2} 0"/>
		<axis xyz="0 0 1"/>
	</joint>

	<link name="servo_bl_link">
		<visual>
			<origin xyz="0 0 0.1"/>
			<geometry>
				<mesh filename="package://holonomic/meshes/servomotor.stl" scale="0.0030 0.0030 0.0026"/>
			</geometry>
			<material name="white"/>
		</visual>

		<collision>
			<origin xyz="0 0 0.1"/>
			<geometry>
				<box size="0.0 0.0 0.0"/>
			</geometry>
		</collision>

		<xacro:inertial_box mass="0.2" x="0.5" y="0.5" z="0.03">
        	<origin xyz="0 0 0.1" rpy="0 0 0"/>
    	</xacro:inertial_box>
	</link>

	<!-- servo fl -->
	<joint name="servo_fl_joint" type="fixed">
		<parent link="base_link"/>
		<child link="servo_fl_link"/>
		<origin xyz="0.19717 0.0 0.1" rpy="${-pi/2} ${-pi/2} 0"/>
		<axis xyz="0 0 1"/>
	</joint>

	<link name="servo_fl_link">
		<visual>
			<origin xyz="0 0 0.1"/>
			<geometry>
				<mesh filename="package://holonomic/meshes/servomotor.stl" scale="0.0030 0.0030 0.0026"/>
			</geometry>
			<material name="white"/>
		</visual>

		<collision>
			<origin xyz="0 0 0.1"/>
			<geometry>
				<box size="0.0 0.0 0.0"/>
			</geometry>
		</collision>

		<xacro:inertial_box mass="0.2" x="0.5" y="0.5" z="0.03">
        	<origin xyz="0 0 0.1" rpy="0 0 0"/>
    	</xacro:inertial_box>
	</link>

	<!-- WHEEL1 LINK -->
	<joint name="wheel1_joint" type="continuous">
		<parent link="base_link"/>
		<child link="wheel1_link"/>
		<origin xyz="0.19717 -0.20 0.08" rpy="${-pi/2} ${-pi/2} 0"/>
		<axis xyz="0 0 1"/>
	</joint>

	<link name="wheel1_link">
		<visual>
			<geometry>
				<mesh filename="package://holonomic/meshes/wheel.stl" scale="0.00172 0.00172 0.00095"/>
			</geometry>
		</visual>

		<collision>
			<geometry>
				<cylinder radius="0.08" length="0.04"/>
			</geometry>
		</collision>

		<xacro:inertial_cylinder mass="0.1" length="0.4" radius="0.8">
        	<origin xyz="0 0 0" rpy="0 0 0"/>
    	</xacro:inertial_cylinder>
	</link>

	<gazebo reference="wheel1_link">
        <material>Gazebo/White</material>
		<mu1 value="0.5"/>
		<mu2 value="0.5"/>
    </gazebo>

	<!-- WHEEL2 LINK -->
	<joint name="wheel2_joint" type="continuous">
		<parent link="base_link"/>
		<child link="wheel2_link"/>
		<origin xyz="-0.19717 -0.20 0.08" rpy="${-pi/2} ${-pi/2} 0"/>
		<axis xyz="0 0 -1"/>
	</joint>

	<link name="wheel2_link">
		<visual>
			<geometry>
				<mesh filename="package://holonomic/meshes/wheel.stl" scale="0.00172 0.00172 0.00095"/>
			</geometry>
		</visual>

		<collision>
			<geometry>
				<cylinder radius="0.08" length="0.04"/>
			</geometry>
		</collision>

		<xacro:inertial_cylinder mass="0.1" length="0.4" radius="0.8">
        	<origin xyz="0 0 0" rpy="0 0 0"/>
    	</xacro:inertial_cylinder>
	</link>

	<gazebo reference="wheel2_link">
        <material>Gazebo/White</material>
		<mu1 value="0.5"/>
		<mu2 value="0.5"/>
    </gazebo>

	<!-- WHEEL3 LINK -->
	<joint name="wheel3_joint" type="continuous">
		<parent link="base_link"/>
		<child link="wheel3_link"/>
		<origin xyz="0.19717 0.20 0.08" rpy="${pi/2} ${-pi/2} 0"/>
		<axis xyz="0 0 1"/>
	</joint>

	<link name="wheel3_link">
		<visual>
			<geometry>
				<mesh filename="package://holonomic/meshes/wheel.stl" scale="0.00172 0.00172 0.00095"/>
			</geometry>
		</visual>

		<collision>
			<geometry>
				<cylinder radius="0.08" length="0.04"/>
			</geometry>
		</collision>

		<xacro:inertial_cylinder mass="0.1" length="0.4" radius="0.8">
        	<origin xyz="0 0 0" rpy="0 0 0"/>
    	</xacro:inertial_cylinder>
	</link>

	<gazebo reference="wheel3_link">
        <material>Gazebo/White</material>
		<mu1 value="0.5"/>
		<mu2 value="0.5"/>
    </gazebo>

	<!-- WHEEL4 LINK -->
	<joint name="wheel4_joint" type="continuous">
		<parent link="base_link"/>
		<child link="wheel4_link"/>
		<origin xyz="-0.19717 0.20 0.08" rpy="${pi/2} ${-pi/2} 0"/>
		<axis xyz="0 0 -1"/>
	</joint>

	<link name="wheel4_link">
		<visual>
			<geometry>
				<mesh filename="package://holonomic/meshes/wheel.stl" scale="0.00172 0.00172 0.00095"/>
			</geometry>
		</visual>

		<collision>
			<geometry>
				<cylinder radius="0.08" length="0.04"/>
			</geometry>
		</collision>

		<xacro:inertial_cylinder mass="0.1" length="0.4" radius="0.8">
        	<origin xyz="0 0 0" rpy="0 0 0"/>
    	</xacro:inertial_cylinder>
	</link>

	<gazebo reference="wheel4_link">
        <material>Gazebo/White</material>
		<mu1 value="0.5"/>
		<mu2 value="0.5"/>
    </gazebo>

	<joint name="cam_ftt_joint" type="fixed">
		<parent link="base_link"/>
		<child link="cam_ftt_link"/>
		<origin xyz="0.088 0.21 0.35" rpy="${pi/2} ${-pi/2} 0"/>
		<axis xyz="0 0 -1"/>
	</joint>

	<link name="cam_ftt_link">
		<visual>
			<origin xyz="0 0 0.1"/>
			<geometry>
				<mesh filename="package://holonomic/meshes/2020_AL-Profile.stl" scale="0.001 0.001 0.022"/>
				<!-- <box size="0.01 0.01 0.77"/> -->
			</geometry>
			<material name="white"/>
		</visual>

		<collision>
			<origin xyz="0 0 0.1"/>
			<geometry>
				<box size="0.0 0.0 0.0"/>
			</geometry>
		</collision>

		<xacro:inertial_box mass="0.2" x="0.5" y="0.5" z="0.03">
        	<origin xyz="0 0 0.1" rpy="0 0 0"/>
    	</xacro:inertial_box>
	</link>

	<joint name="cam_1_joint" type="fixed">
		<parent link="base_link"/>
		<child link="cam_1_link"/>
		<origin xyz="0.076 -0.07 0.24" rpy="0 0 0"/>
		<axis xyz="0 0 -1"/>
	</joint> 

	<link name="cam_1_link">
		<visual>
			<origin xyz="0 0 0.1" rpy="0 0.15 0"/>
			<geometry>
				<box size="0.03 0.03 0.03"/>
			</geometry>
			<material name="white"/>
		</visual>

		<collision>
			<origin xyz="0 0 0.1"/>
			<geometry>
				<box size="0.0 0.0 0.0"/>
			</geometry>
		</collision>

		<xacro:inertial_box mass="0.2" x="0.5" y="0.5" z="0.03">
        	<origin xyz="0 0 0.1" rpy="0 0 0"/>
    	</xacro:inertial_box>
	</link>

	<joint name="cam_2_joint" type="fixed">
		<parent link="base_link"/>
		<child link="cam_2_link"/>
		<origin xyz="0.076 0.07 0.24" rpy="0 0 0"/>
		<axis xyz="0 0 -10"/>
	</joint>

	<link name="cam_2_link">
		<visual>
			<origin xyz="0 0 0.1" rpy="0 0.50 0"/>
			<geometry>
				<box size="0.03 0.03 0.03"/>
			</geometry>
			<material name="white"/>
		</visual>

		<collision>
			<origin xyz="0 0 0.1"/>
			<geometry>
				<box size="0.0 0.0 0.0"/>
			</geometry>
		</collision>

		<xacro:inertial_box mass="0.2" x="0.5" y="0.5" z="0.03">
        	<origin xyz="0 0 0.1" rpy="0 0 0"/>
    	</xacro:inertial_box>
	</link>

	<joint name="cam_pole_1_link_joint" type="fixed">
		<parent link="base_link"/>
		<child link="cam_pole_1_link"/>
		<origin xyz="0.07 0.105 0.03" rpy="0 0 0"/>
		<axis xyz="0 0 -1"/>
	</joint>

	<link name="cam_pole_1_link">
		<visual>
			<origin xyz="0 0 0.1"/>
			<geometry>
				<mesh filename="package://holonomic/meshes/2020_AL-Profile.stl" scale="0.001 0.001 0.025"/>
			</geometry>
			<material name="white"/>
		</visual>

		<collision>
			<origin xyz="0 0 0.1"/>
			<geometry>
				<box size="0.0 0.0 0.0"/>
			</geometry>
		</collision>

		<xacro:inertial_box mass="0.2" x="0.5" y="0.5" z="0.03">
        	<origin xyz="0 0 0.1" rpy="0 0 0"/>
    	</xacro:inertial_box>
	</link>

	<joint name="cam_pole_2_link_joint" type="fixed">
		<parent link="base_link"/>
		<child link="cam_pole_2_link"/>
		<origin xyz="0.07 -0.125 0.03" rpy="0 0 0"/>
		<axis xyz="0 0 -1"/>
	</joint>

	<link name="cam_pole_2_link">
		<visual>
			<origin xyz="0 0 0.1"/>
			<geometry>
				<mesh filename="package://holonomic/meshes/2020_AL-Profile.stl" scale="0.001 0.001 0.025"/>
			</geometry>
			<material name="white"/>
		</visual>

		<collision>
			<origin xyz="0 0 0.1"/>
			<geometry>
				<box size="0.0 0.0 0.0"/>
			</geometry>
		</collision>

		<xacro:inertial_box mass="0.2" x="0.5" y="0.5" z="0.03">
        	<origin xyz="0 0 0.1" rpy="0 0 0"/>
    	</xacro:inertial_box>
	</link>
</robot>
